============================= test session starts ==============================
platform darwin -- Python 3.11.9, pytest-7.4.3, pluggy-1.6.0
rootdir: /Users/b/--NeuroCore--/AIFOLIO/AIFOLIO_FINAL_V12/backend
plugins: anyio-3.7.1
collected 0 items / 1 error

==================================== ERRORS ====================================
_____________________ ERROR collecting test_pmp_service.py _____________________
/Users/b/.pyenv/versions/3.11.9/lib/python3.11/site-packages/_pytest/runner.py:341: in from_call
    result: Optional[TResult] = func()
/Users/b/.pyenv/versions/3.11.9/lib/python3.11/site-packages/_pytest/runner.py:372: in <lambda>
    call = CallInfo.from_call(lambda: list(collector.collect()), "collect")
/Users/b/.pyenv/versions/3.11.9/lib/python3.11/site-packages/_pytest/python.py:531: in collect
    self._inject_setup_module_fixture()
/Users/b/.pyenv/versions/3.11.9/lib/python3.11/site-packages/_pytest/python.py:545: in _inject_setup_module_fixture
    self.obj, ("setUpModule", "setup_module")
/Users/b/.pyenv/versions/3.11.9/lib/python3.11/site-packages/_pytest/python.py:310: in obj
    self._obj = obj = self._getobj()
/Users/b/.pyenv/versions/3.11.9/lib/python3.11/site-packages/_pytest/python.py:528: in _getobj
    return self._importtestmodule()
/Users/b/.pyenv/versions/3.11.9/lib/python3.11/site-packages/_pytest/python.py:617: in _importtestmodule
    mod = import_path(self.path, mode=importmode, root=self.config.rootpath)
/Users/b/.pyenv/versions/3.11.9/lib/python3.11/site-packages/_pytest/pathlib.py:567: in import_path
    importlib.import_module(module_name)
/Users/b/.pyenv/versions/3.11.9/lib/python3.11/importlib/__init__.py:126: in import_module
    return _bootstrap._gcd_import(name[level:], package, level)
<frozen importlib._bootstrap>:1204: in _gcd_import
    ???
<frozen importlib._bootstrap>:1176: in _find_and_load
    ???
<frozen importlib._bootstrap>:1147: in _find_and_load_unlocked
    ???
<frozen importlib._bootstrap>:690: in _load_unlocked
    ???
/Users/b/.pyenv/versions/3.11.9/lib/python3.11/site-packages/_pytest/assertion/rewrite.py:186: in exec_module
    exec(co, module.__dict__)
test_pmp_service.py:16: in <module>
    client = TestClient(app)
/Users/b/.pyenv/versions/3.11.9/lib/python3.11/site-packages/starlette/testclient.py:399: in __init__
    super().__init__(
E   TypeError: Client.__init__() got an unexpected keyword argument 'app'
------------------------------- Captured stdout --------------------------------
DIAG: starlette version: 0.27.0
DIAG: TestClient type: <class 'type'>
DIAG: TestClient module: starlette.testclient
DIAG: starlette.testclient file: /Users/b/.pyenv/versions/3.11.9/lib/python3.11/site-packages/starlette/testclient.py
DIAG: TestClient file: /Users/b/.pyenv/versions/3.11.9/lib/python3.11/site-packages/starlette/testclient.py
=========================== short test summary info ============================
ERROR test_pmp_service.py - TypeError: Client.__init__() got an unexpected ke...
!!!!!!!!!!!!!!!!!!!!!!!!!! stopping after 1 failures !!!!!!!!!!!!!!!!!!!!!!!!!!!
=============================== 1 error in 0.33s ===============================
